<?xml version="1.0" encoding="utf-8"?>
<!-- This URDF was automatically created by SolidWorks to URDF Exporter! Originally created by Stephen Brawner (brawner@gmail.com) 
     Commit Version: 1.6.0-4-g7f85cfe  Build Version: 1.6.7995.38578
     For more information, please see http://wiki.ros.org/sw_urdf_exporter -->
<robot
  name="xt_dog">
  <link
    name="base">
    <inertial>
      <origin
        xyz="-6.8387E-05 -0.00051279 0.062014"
        rpy="0 0 0" />
      <mass
        value="8.9114" />
      <inertia
        ixx="0.061528"
        ixy="6.16E-05"
        ixz="0.0002485"
        iyy="0.12748"
        iyz="7.84E-05"
        izz="0.15915" />
    </inertial>
    <visual>
      <origin
        xyz="0 0 0"
        rpy="0 0 0" />
      <geometry>
        <mesh
          filename="../meshes/base.STL" />
      </geometry>
      <material
        name="">
        <color
          rgba="0.89804 0.91765 0.92941 1" />
      </material>
    </visual>
    <collision>
      <origin
        xyz="0 0 0"
        rpy="0 0 0" />
      <geometry>
        <mesh
          filename="../meshes/base.STL" />
      </geometry>
    </collision>
  </link>
  <link
    name="FL_hip">
    <inertial>
      <origin
        xyz="-0.009071 -0.00066921 0.0030017"
        rpy="0 0 0" />
      <mass
        value="1.7307" />
      <inertia
        ixx="0.0022205"
        ixy="6.23E-05"
        ixz="-1.38E-05"
        iyy="0.0039266"
        iyz="-3.12E-05"
        izz="0.002753" />
    </inertial>
    <visual>
      <origin
        xyz="0 0 0"
        rpy="0 0 0" />
      <geometry>
        <mesh
          filename="../meshes/FL_hip.STL" />
      </geometry>
      <material
        name="">
        <color
          rgba="0.61176 0.65882 0.67059 1" />
      </material>
    </visual>
    <collision>
      <origin
        xyz="0 0 0"
        rpy="0 0 0" />
      <geometry>
        <mesh
          filename="../meshes/FL_hip.STL" />
      </geometry>
    </collision>
  </link>
  <joint
    name="FL_hip_joint"
    type="revolute">
    <origin
      xyz="0.22493 0.062028 0.058665"
      rpy="0 0 0" />
    <parent
      link="base" />
    <child
      link="FL_hip" />
    <axis
      xyz="1 0 0" />
    <limit
      lower="-0.7854 "
      upper="0.7854"
      effort="40"
      velocity="20" />
  </joint>
  <link
    name="FL_thigh">
    <inertial>
      <origin
        xyz="-0.0064856 0.0035106 -0.018791"
        rpy="0 0 0" />
      <mass
        value="2.5793" />
      <inertia
        ixx="0.010577"
        ixy="0.0005158"
        ixz="-0.0024329"
        iyy="0.01186"
        iyz="0.0014743"
        izz="0.0044128" />
    </inertial>
    <visual>
      <origin
        xyz="0 0 0"
        rpy="0 0 0" />
      <geometry>
        <mesh
          filename="../meshes/FL_thigh.STL" />
      </geometry>
      <material
        name="">
        <color
          rgba="1 1 1 1" />
      </material>
    </visual>
    <collision>
      <origin
        xyz="0 0 0"
        rpy="0 0 0" />
      <geometry>
        <mesh
          filename="../meshes/FL_thigh.STL" />
      </geometry>
    </collision>
  </link>
  <joint
    name="FL_thigh_joint"
    type="revolute">
    <origin
      xyz="-0.0009767 0.068078 0.0016177"
      rpy="0 0 0" />
    <parent
      link="FL_hip" />
    <child
      link="FL_thigh" />
    <axis
      xyz="0 1 0" />
    <limit
       lower="-1.8326"
      upper="1.8326"
      effort="40"
      velocity="20" />
  </joint>
  <link
    name="FL_calf">
    <inertial>
      <origin
        xyz="0.031152 -0.0031243 -0.10209"
        rpy="0 0 0" />
      <mass
        value="0.3664" />
      <inertia
        ixx="0.0027904"
        ixy="2.46E-05"
        ixz="0.0008267"
        iyy="0.0030728"
        iyz="-8.15E-05"
        izz="0.0003331" />
    </inertial>
    <visual>
      <origin
        xyz="0 0 0"
        rpy="0 0 0" />
      <geometry>
        <mesh
          filename="../meshes/FL_calf.STL" />
      </geometry>
      <material
        name="">
        <color
          rgba="0.89804 0.91765 0.92941 1" />
      </material>
    </visual>
    <collision>
      <origin
        xyz="0 0 0"
        rpy="0 0 0" />
      <geometry>
        <mesh
          filename="../meshes/FL_calf.STL" />
      </geometry>
    </collision>
  </link>
  <joint
    name="FL_calf_joint"
    type="revolute">
    <origin
      xyz="-0.088525 0.031884 -0.25614"
      rpy="0 0 0" />
    <parent
      link="FL_thigh" />
    <child
      link="FL_calf" />
    <axis
      xyz="0 1 0" />
    <limit
      lower="-1.8326"
      upper="0.5236"
      effort="40"
      velocity="20" />
  </joint>
  <link
    name="FL_foot">
    <inertial>
      <origin
        xyz="0 -2.2204E-16 -1.1102E-16"
        rpy="0 0 0" />
      <mass
        value="0.1315" />
      <inertia
        ixx="4.73E-05"
        ixy="0"
        ixz="0"
        iyy="4.73E-05"
        iyz="0"
        izz="4.73E-05" />
    </inertial>
    <visual>
      <origin
        xyz="0 0 0"
        rpy="0 0 0" />
      <geometry>
        <mesh
          filename="../meshes/FL_foot.STL" />
      </geometry>
      <material
        name="">
        <color
          rgba="0 0 0 1" />
      </material>
    </visual>
    <collision>
      <origin
        xyz="0 0 0"
        rpy="0 0 0" />
      <geometry>
        <mesh
          filename="../meshes/FL_foot.STL" />
      </geometry>
    </collision>
  </link>
  <joint
    name="FL_foot_joint"
    type="fixed">
    <origin
      xyz="0.084015 -0.0082942 -0.27535"
      rpy="0 0 0" />
    <parent
      link="FL_calf" />
    <child
      link="FL_foot" />
    <axis
      xyz="0 0 0" />
  </joint>
  <link
    name="FR_hip">
    <inertial>
      <origin
        xyz="-0.007193 0.00085492 0.002813"
        rpy="0 0 0" />
      <mass
        value="1.7307" />
      <inertia
        ixx="0.0022388"
        ixy="-6.88E-05"
        ixz="2.83E-05"
        iyy="0.003903"
        iyz="-2.88E-05"
        izz="0.0027126" />
    </inertial>
    <visual>
      <origin
        xyz="0 0 0"
        rpy="0 0 0" />
      <geometry>
        <mesh
          filename="../meshes/FR_hip.STL" />
      </geometry>
      <material
        name="">
        <color
          rgba="0.61176 0.65882 0.67059 1" />
      </material>
    </visual>
    <collision>
      <origin
        xyz="0 0 0"
        rpy="0 0 0" />
      <geometry>
        <mesh
          filename="../meshes/FR_hip.STL" />
      </geometry>
    </collision>
  </link>
  <joint
    name="FR_hip_joint"
    type="revolute">
    <origin
      xyz="0.2225 -0.062529 0.05888"
      rpy="0 0 0" />
    <parent
      link="base" />
    <child
      link="FR_hip" />
    <axis
      xyz="1 0 0" />
    <limit
    lower="-0.7854 "
      upper="0.7854"
      effort="40"
      velocity="20" />
  </joint>
  <link
    name="FR_thigh">
    <inertial>
      <origin
        xyz="-0.0063846 -0.004616 -0.018585"
        rpy="0 0 0" />
      <mass
        value="2.5793" />
      <inertia
        ixx="0.010622"
        ixy="-0.0006479"
        ixz="-0.0023408"
        iyy="0.01166"
        iyz="-0.0019079"
        izz="0.004568" />
    </inertial>
    <visual>
      <origin
        xyz="0 0 0"
        rpy="0 0 0" />
      <geometry>
        <mesh
          filename="../meshes/FR_thigh.STL" />
      </geometry>
      <material
        name="">
        <color
          rgba="1 1 1 1" />
      </material>
    </visual>
    <collision>
      <origin
        xyz="0 0 0"
        rpy="0 0 0" />
      <geometry>
        <mesh
          filename="../meshes/FR_thigh.STL" />
      </geometry>
    </collision>
  </link>
  <joint
    name="FR_thigh_joint"
    type="revolute">
    <origin
      xyz="0.00095427 -0.067864 0.0056446"
      rpy="0 0 0" />
    <parent
      link="FR_hip" />
    <child
      link="FR_thigh" />
    <axis
      xyz="0 1 0" />
    <limit
      lower="-1.8326"
      upper="1.8326"
      effort="40"
      velocity="20" />
  </joint>
  <link
    name="FR_calf">
    <inertial>
      <origin
        xyz="0.030284 -0.0030805 -0.10195"
        rpy="0 0 0" />
      <mass
        value="0.3664" />
      <inertia
        ixx="0.0028129"
        ixy="2.38E-05"
        ixz="0.0008114"
        iyy="0.0030841"
        iyz="-8.11E-05"
        izz="0.0003219" />
    </inertial>
    <visual>
      <origin
        xyz="0 0 0"
        rpy="0 0 0" />
      <geometry>
        <mesh
          filename="../meshes/FR_calf.STL" />
      </geometry>
      <material
        name="">
        <color
          rgba="0.89804 0.91765 0.92941 1" />
      </material>
    </visual>
    <collision>
      <origin
        xyz="0 0 0"
        rpy="0 0 0" />
      <geometry>
        <mesh
          filename="../meshes/FR_calf.STL" />
      </geometry>
    </collision>
  </link>
  <joint
    name="FR_calf_joint"
    type="revolute">
    <origin
      xyz="-0.08723 -0.04698 -0.25425"
      rpy="0 0 0" />
    <parent
      link="FR_thigh" />
    <child
      link="FR_calf" />
    <axis
      xyz="0 1 0" />
    <limit
     lower="-1.8326"
      upper="0.5236"
      effort="40"
      velocity="20" />
  </joint>
  <link
    name="FR_foot">
    <inertial>
      <origin
        xyz="1.1102E-16 -1.1102E-16 0"
        rpy="0 0 0" />
      <mass
        value="0.1315" />
      <inertia
        ixx="4.73E-05"
        ixy="0"
        ixz="0"
        iyy="4.73E-05"
        iyz="0"
        izz="4.73E-05" />
    </inertial>
    <visual>
      <origin
        xyz="0 0 0"
        rpy="0 0 0" />
      <geometry>
        <mesh
          filename="../meshes/FR_foot.STL" />
      </geometry>
      <material
        name="">
        <color
          rgba="0 0 0 1" />
      </material>
    </visual>
    <collision>
      <origin
        xyz="0 0 0"
        rpy="0 0 0" />
      <geometry>
        <mesh
          filename="../meshes/FR_foot.STL" />
      </geometry>
    </collision>
  </link>
  <joint
    name="FR_foot_joint"
    type="fixed">
    <origin
      xyz="0.081967 -0.0081882 -0.27597"
      rpy="0 0 0" />
    <parent
      link="FR_calf" />
    <child
      link="FR_foot" />
    <axis
      xyz="0 0 0" />
  </joint>
  <link
    name="RL_hip">
    <inertial>
      <origin
        xyz="0.0087401 -0.00085607 -0.0029571"
        rpy="0 0 0" />
      <mass
        value="1.7307" />
      <inertia
        ixx="0.002229"
        ixy="-6.16E-05"
        ixz="-1.05E-05"
        iyy="0.0039131"
        iyz="-3.55E-05"
        izz="0.0027333" />
    </inertial>
    <visual>
      <origin
        xyz="0 0 0"
        rpy="0 0 0" />
      <geometry>
        <mesh
          filename="../meshes/RL_hip.STL" />
      </geometry>
      <material
        name="">
        <color
          rgba="0.61176 0.65882 0.67059 1" />
      </material>
    </visual>
    <collision>
      <origin
        xyz="0 0 0"
        rpy="0 0 0" />
      <geometry>
        <mesh
          filename="../meshes/RL_hip.STL" />
      </geometry>
    </collision>
  </link>
  <joint
    name="RL_hip_joint"
    type="revolute">
    <origin
      xyz="-0.22443 0.062366 0.065266"
      rpy="0 0 0" />
    <parent
      link="base" />
    <child
      link="RL_hip" />
    <axis
      xyz="1 0 0" />
    <limit
     lower="-0.7854 "
      upper="0.7854"
      effort="40"
      velocity="20" />
  </joint>
  <link
    name="RL_thigh">
    <inertial>
      <origin
        xyz="-0.0068764 0.0035707 -0.01864"
        rpy="0 0 0" />
      <mass
        value="2.5793" />
      <inertia
        ixx="0.010473"
        ixy="0.0005551"
        ixz="-0.0025578"
        iyy="0.011851"
        iyz="0.0014867"
        izz="0.0045259" />
    </inertial>
    <visual>
      <origin
        xyz="0 0 0"
        rpy="0 0 0" />
      <geometry>
        <mesh
          filename="../meshes/RL_thigh.STL" />
      </geometry>
      <material
        name="">
        <color
          rgba="1 1 1 1" />
      </material>
    </visual>
    <collision>
      <origin
        xyz="0 0 0"
        rpy="0 0 0" />
      <geometry>
        <mesh
          filename="../meshes/RL_thigh.STL" />
      </geometry>
    </collision>
  </link>
  <joint
    name="RL_thigh_joint"
    type="revolute">
    <origin
      xyz="0.0009767 0.067878 -0.0054656"
      rpy="0 0 0" />
    <parent
      link="RL_hip" />
    <child
      link="RL_thigh" />
    <axis
      xyz="0 1 0" />
    <limit
       lower="-1.8326"
      upper="1.8326"
      effort="40"
      velocity="20" />
  </joint>
  <link
    name="RL_calf">
    <inertial>
      <origin
        xyz="0.041192 -8.1501E-05 -0.098523"
        rpy="0 0 0" />
      <mass
        value="0.3664" />
      <inertia
        ixx="0.0026016"
        ixy="-1E-07"
        ixz="0.0010549"
        iyy="0.0030752"
        iyz="2E-07"
        izz="0.0005195" />
    </inertial>
    <visual>
      <origin
        xyz="0 0 0"
        rpy="0 0 0" />
      <geometry>
        <mesh
          filename="../meshes/RL_calf.STL" />
      </geometry>
      <material
        name="">
        <color
          rgba="0.89804 0.91765 0.92941 1" />
      </material>
    </visual>
    <collision>
      <origin
        xyz="0 0 0"
        rpy="0 0 0" />
      <geometry>
        <mesh
          filename="../meshes/RL_calf.STL" />
      </geometry>
    </collision>
  </link>
  <joint
    name="RL_calf_joint"
    type="revolute">
    <origin
      xyz="-0.093862 0.032703 -0.25413"
      rpy="0 0 0" />
    <parent
      link="RL_thigh" />
    <child
      link="RL_calf" />
    <axis
      xyz="0 1 0" />
    <limit
     lower="-1.8326"
      upper="0.5236"
      effort="40"
      velocity="20" />
  </joint>
  <link
    name="RL_foot">
    <inertial>
      <origin
        xyz="-1.1102E-16 -1.1102E-16 0"
        rpy="0 0 0" />
      <mass
        value="0.1315" />
      <inertia
        ixx="4.73E-05"
        ixy="0"
        ixz="0"
        iyy="4.73E-05"
        iyz="0"
        izz="4.73E-05" />
    </inertial>
    <visual>
      <origin
        xyz="0 0 0"
        rpy="0 0 0" />
      <geometry>
        <mesh
          filename="../meshes/RL_foot.STL" />
      </geometry>
      <material
        name="">
        <color
          rgba="0 0 0 1" />
      </material>
    </visual>
    <collision>
      <origin
        xyz="0 0 0"
        rpy="0 0 0" />
      <geometry>
        <mesh
          filename="../meshes/RL_foot.STL" />
      </geometry>
    </collision>
  </link>
  <joint
    name="RL_foot_joint"
    type="fixed">
    <origin
      xyz="0.11109 -8.7868E-05 -0.26571"
      rpy="0 0 0" />
    <parent
      link="RL_calf" />
    <child
      link="RL_foot" />
    <axis
      xyz="0 0 0" />
  </joint>
  <link
    name="RR_hip">
    <inertial>
      <origin
        xyz="0.0071803 0.00077627 -0.0028368"
        rpy="0 0 0" />
      <mass
        value="1.7307" />
      <inertia
        ixx="0.0022392"
        ixy="6.92E-05"
        ixz="2.63E-05"
        iyy="0.0039035"
        iyz="-6E-06"
        izz="0.0027115" />
    </inertial>
    <visual>
      <origin
        xyz="0 0 0"
        rpy="0 0 0" />
      <geometry>
        <mesh
          filename="../meshes/RR_hip.STL" />
      </geometry>
      <material
        name="">
        <color
          rgba="0.61176 0.65882 0.67059 1" />
      </material>
    </visual>
    <collision>
      <origin
        xyz="0 0 0"
        rpy="0 0 0" />
      <geometry>
        <mesh
          filename="../meshes/RR_hip.STL" />
      </geometry>
    </collision>
  </link>
  <joint
    name="RR_hip_joint"
    type="revolute">
    <origin
      xyz="-0.2225 -0.062221 0.065531"
      rpy="0 0 0" />
    <parent
      link="base" />
    <child
      link="RR_hip" />
    <axis
      xyz="1 0 0" />
    <limit
     lower="-0.7854 "
      upper="0.7854"
      effort="40"
      velocity="20" />
  </joint>
  <link
    name="RR_thigh">
    <inertial>
      <origin
        xyz="-0.0066684 -0.004061 -0.018591"
        rpy="0 0 0" />
      <mass
        value="2.5793" />
      <inertia
        ixx="0.010524"
        ixy="-0.0006048"
        ixz="-0.0024767"
        iyy="0.011762"
        iyz="-0.0016862"
        izz="0.004556" />
    </inertial>
    <visual>
      <origin
        xyz="0 0 0"
        rpy="0 0 0" />
      <geometry>
        <mesh
          filename="../meshes/RR_thigh.STL" />
      </geometry>
      <material
        name="">
        <color
          rgba="1 1 1 1" />
      </material>
    </visual>
    <collision>
      <origin
        xyz="0 0 0"
        rpy="0 0 0" />
      <geometry>
        <mesh
          filename="../meshes/RR_thigh.STL" />
      </geometry>
    </collision>
  </link>
  <joint
    name="RR_thigh_joint"
    type="revolute">
    <origin
      xyz="-0.00095427 -0.068 -0.003651"
      rpy="0 0 0" />
    <parent
      link="RR_hip" />
    <child
      link="RR_thigh" />
    <axis
      xyz="0 1 0" />
    <limit
       lower="-1.8326"
      upper="1.8326"
      effort="40"
      velocity="20" />
  </joint>
  <link
    name="RR_calf">
    <inertial>
      <origin
        xyz="0.041008 8.7844E-05 -0.098181"
        rpy="0 0 0" />
      <mass
        value="0.3664" />
      <inertia
        ixx="0.002612"
        ixy="0"
        ixz="0.0010581"
        iyy="0.0030865"
        iyz="0"
        izz="0.0005204" />
    </inertial>
    <visual>
      <origin
        xyz="0 0 0"
        rpy="0 0 0" />
      <geometry>
        <mesh
          filename="../meshes/RR_calf.STL" />
      </geometry>
      <material
        name="">
        <color
          rgba="0.89804 0.91765 0.92941 1" />
      </material>
    </visual>
    <collision>
      <origin
        xyz="0 0 0"
        rpy="0 0 0" />
      <geometry>
        <mesh
          filename="../meshes/RR_calf.STL" />
      </geometry>
    </collision>
  </link>
  <joint
    name="RR_calf_joint"
    type="revolute">
    <origin
      xyz="-0.091121 -0.0395 -0.25416"
      rpy="0 0 0" />
    <parent
      link="RR_thigh" />
    <child
      link="RR_calf" />
    <axis
      xyz="0 1 0" />
    <limit
    lower="-1.8326"
      upper="0.5236"
      effort="40"
      velocity="20" />
  </joint>
  <link
    name="RR_foot">
    <inertial>
      <origin
        xyz="0 0 0"
        rpy="0 0 0" />
      <mass
        value="0.1315" />
      <inertia
        ixx="4.73E-05"
        ixy="0"
        ixz="0"
        iyy="4.73E-05"
        iyz="0"
        izz="4.73E-05" />
    </inertial>
    <visual>
      <origin
        xyz="0 0 0"
        rpy="0 0 0" />
      <geometry>
        <mesh
          filename="../meshes/RR_foot.STL" />
      </geometry>
      <material
        name="">
        <color
          rgba="0 0 0 1" />
      </material>
    </visual>
    <collision>
      <origin
        xyz="0 0 0"
        rpy="0 0 0" />
      <geometry>
        <mesh
          filename="../meshes/RR_foot.STL" />
      </geometry>
    </collision>
  </link>
  <joint
    name="RR_foot_joint"
    type="fixed">
    <origin
      xyz="0.111 8.7868E-05 -0.26575"
      rpy="0 0 0" />
    <parent
      link="RR_calf" />
    <child
      link="RR_foot" />
    <axis
      xyz="0 0 0" />
  </joint>
</robot>